Workbook

Sheet Notas
A1: Caso: elección de tecnología de comunicación IoT/WSN para Palmor
A3: Réplica guiada de Sesión 2. Elegir la tecnología de comunicación (LoRaWAN, GSM/GPRS, Sigfox, Zigbee) para una red de sensores IoT/WSN de monitoreo agroclimático en Palmor, corregimiento de Ciénaga, Sierra Nevada de Santa Marta; criterios: Alcance, Autonomía, Infraestructura, Madurez.
A4: Cada juicio es la media geométrica de un panel de 3 expertos (ingeniero electrónico, ingeniero agrónomo, técnico de campo), no la opinión de una sola persona, ver hoja Criterios (filas 26+) para el mecanismo de agregación (Forman & Peniwati, 1998, EJOR 108:165-169).
A5: Orden de hojas: Criterios → Alcance → Autonomía → Infraestructura → Madurez → Síntesis
A6: Cómo usarlo: en Criterios ya está armada la matriz agregada de los 3 expertos (celdas GEOMEAN, filas 3-6) y, más abajo (filas 26+), los 3 juicios individuales que la alimentan. En cada hoja de alternativa (Alcance, Autonomía, Infraestructura, Madurez) solo debe verificar la matriz ya agregada, su vector de prioridad y su CR. Al final, la hoja Síntesis combina los 4 vectores con los pesos de Criterios y calcula el ranking y el ganador automáticamente.
A7: ¿Qué es GEOMEAN()? Es la media geométrica (la raíz n-ésima del producto de n números), la función de Excel que la hoja Criterios usa para combinar el mismo juicio de los 3 expertos en un solo número. No es el promedio normal (aritmético, =AVERAGE()): la media geométrica es la que preserva la propiedad recíproca a_ji=1/a_ij de una matriz AHP, el promedio aritmético la rompe (Forman & Peniwati, 1998).
A8: Revise siempre la fila "¿Consistente? (CR < 0.10)" de cada hoja antes de dar los juicios por buenos.

Sheet Criterios
A1: AHP, Criterios | B1: Media geométrica de 3 expertos (Forman & Peniwati, 1998), ver juicios individuales más abajo (filas 26+)
B2: EFICIENCIA DE DATOS | C2: METRICAS WER/CER | D2: MADUREZ Y SOPORTE DE HERRAMIENTAS | E2: DEPENDENCIA DE ANOTACION | F2: TRANSFERIBILIDAD ENTRE LENGUAS
A3: EFICIENCIA DE DATOS | B3: 1 | C3: =GEOMEAN(C32,C40,C48) -> #NUM! | D3: =GEOMEAN(D32,D40,D48) -> #NUM! | E3: =GEOMEAN(E32,E40,E48) -> #NUM! | F3: =GEOMEAN(F32,F40,F48) -> #NUM!
A4: METRICAS WER/CER | B4: =1/C3 -> #NUM! | C4: 1 | D4: =GEOMEAN(D33,D41,D49) -> #NUM! | E4: =GEOMEAN(E33,E41,E49) -> #NUM! | F4: =GEOMEAN(F33,F41,F49) -> #NUM!
A5: MADUREZ Y SOPORTE DE HERRAMIENTAS | B5: =1/D3 -> #NUM! | C5: =1/D4 -> #NUM! | D5: 1 | E5: =GEOMEAN(E34,E42,E50) -> #NUM! | F5: =GEOMEAN(F34,F42,F50) -> #NUM!
A6: DEPENDENCIA DE ANOTACION | B6: =1/E3 -> #NUM! | C6: =1/E4 -> #NUM! | D6: =1/E5 -> #NUM! | E6: 1 | F6: =GEOMEAN(F35,F43,F51) -> #NUM!
A7: TRANSFERIBILIDAD ENTRE LENGUAS | B7: =1/F3 -> #NUM! | C7: =1/F4 -> #NUM! | D7: =1/F5 -> #NUM! | E7: =1/F6 -> #NUM! | F7: 1
A8: Suma | B8: =SUM(B3:B6) -> #NUM! | C8: =SUM(C3:C6) -> #NUM! | D8: =SUM(D3:D6) -> #NUM! | E8: =SUM(E3:E6) -> #NUM! | F8: =SUM(F3:F6) -> #NUM!
A10: Normalizada | F10: Vector prioridad
A11: EFICIENCIA DE DATOS | B11: =B3/B$8 -> #NUM! | C11: =C3/C$8 -> #NUM! | D11: =D3/D$8 -> #NUM! | E11: =E3/E$8 -> #NUM! | F11: =AVERAGE(B11:E11) -> #NUM!
A12: METRICAS WER/CER | B12: =B4/B$8 -> #NUM! | C12: =C4/C$8 -> #NUM! | D12: =D4/D$8 -> #NUM! | E12: =E4/E$8 -> #NUM! | F12: =AVERAGE(B12:E12) -> #NUM!
A13: MADUREZ Y SOPORTE DE HERRAMIENTAS | B13: =B5/B$8 -> #NUM! | C13: =C5/C$8 -> #NUM! | D13: =D5/D$8 -> #NUM! | E13: =E5/E$8 -> #NUM! | F13: =AVERAGE(B13:E13) -> #NUM!
A14: DEPENDENCIA DE ANOTACION | B14: =B6/B$8 -> #NUM! | C14: =C6/C$8 -> #NUM! | D14: =D6/D$8 -> #NUM! | E14: =E6/E$8 -> #NUM! | F14: =AVERAGE(B14:E14) -> #NUM!
A15: TRANSFERIBILIDAD ENTRE LENGUAS | B15: =B7/B$8 -> #NUM! | C15: =C7/C$8 -> #NUM! | D15: =D7/D$8 -> #NUM! | E15: =E7/E$8 -> #NUM! | F15: =AVERAGE(B15:E15) -> #NUM!
A17: Verificación de consistencia
A18: A·w (Alcance) | B18: =B3*$F$11 + C3*$F$12 + D3*$F$13 + E3*$F$14 -> #NUM! | C18: =B18/F11 -> #NUM! | D18: lambda parcial
A19: A·w (Autonomía) | B19: =B4*$F$11 + C4*$F$12 + D4*$F$13 + E4*$F$14 -> #NUM! | C19: =B19/F12 -> #NUM! | D19: lambda parcial
A20: A·w (Infraestructura) | B20: =B5*$F$11 + C5*$F$12 + D5*$F$13 + E5*$F$14 -> #NUM! | C20: =B20/F13 -> #NUM! | D20: lambda parcial
A21: A·w (Madurez) | B21: =B6*$F$11 + C6*$F$12 + D6*$F$13 + E6*$F$14 -> #NUM! | C21: =B21/F14 -> #NUM! | D21: lambda parcial
A22: lambda_max | B22: =AVERAGE(C18:C21) -> #NUM!
A23: CI = (lambda_max - n) / (n - 1) | B23: =(B22-4)/(4-1) -> #NUM!
A24: RI (tabla Saaty, n=5) | B24: 1.12
A25: CR = CI / RI | B25: =B23/B24 -> #NUM!
A26: ¿Consistente? (CR < 0.10) | B26: =IF(B25<0.1,"Sí, consistente","No, revisar juicios") -> #NUM!
A28: Juicios individuales de los 3 expertos (entrada de GEOMEAN() de arriba)
A30: Experto 1: Ingeniero/investigador en Machine Learning o procesamiento de voz (ASR)
B31: EFICIENCIA DE DATOS | C31: METRICAS WER/CER | D31: MADUREZ Y SOPORTE DE HERRAMIENTAS | E31: DEPENDENCIA DE ANOTACION | F31: TRANSFERIBILIDAD ENTRE LENGUAS
A32: EFICIENCIA DE DATOS | B32: 1
A33: METRICAS WER/CER | B33: =1/C32 -> #DIV/0! | C33: 1
A34: MADUREZ Y SOPORTE DE HERRAMIENTAS | B34: =1/D32 -> #DIV/0! | C34: =1/D33 -> #DIV/0! | D34: 1
A35: DEPENDENCIA DE ANOTACION | B35: =1/E32 -> #DIV/0! | C35: =1/E33 -> #DIV/0! | D35: =1/E34 -> #DIV/0! | E35: 1
A36: TRANSFERIBILIDAD ENTRE LENGUAS | B36: =1/F32 -> #DIV/0! | C36: =1/F33 -> #DIV/0! | D36: =1/F34 -> #DIV/0! | E36: =1/F35 -> #DIV/0! | F36: 1
A38: Experto 2: Ingeniero electrónico, procesamiento de señales
B39: EFICIENCIA DE DATOS | C39: METRICAS WER/CER | D39: MADUREZ Y SOPORTE DE HERRAMIENTAS | E39: DEPENDENCIA DE ANOTACION | F39: TRANSFERIBILIDAD ENTRE LENGUAS
A40: EFICIENCIA DE DATOS | B40: 1
A41: METRICAS WER/CER | B41: =1/C40 -> #DIV/0! | C41: 1
A42: MADUREZ Y SOPORTE DE HERRAMIENTAS | B42: =1/D40 -> #DIV/0! | C42: =1/D41 -> #DIV/0! | D42: 1
A43: DEPENDENCIA DE ANOTACION | B43: =1/E40 -> #DIV/0! | C43: =1/E41 -> #DIV/0! | D43: =1/E42 -> #DIV/0! | E43: 1
A44: TRANSFERIBILIDAD ENTRE LENGUAS | B44: =1/F40 -> #DIV/0! | C44: =1/F41 -> #DIV/0! | D44: =1/F42 -> #DIV/0! | E44: =1/F43 -> #DIV/0! | F44: 1
A46: Experto 3: Hablante nativo colaborador
...

Sheet Alcance
A1: AHP, Alcance | B1: Media geométrica de 3 expertos (ver juicios individuales más abajo, filas 26+). Sigfox 30-50km >> LoRaWAN/GSM-GPRS 5-16km >> Zigbee 10-100m
B2: LoRaWAN | C2: GSM/GPRS | D2: Sigfox | E2: Zigbee
A3: LoRaWAN | B3: 1 | C3: =GEOMEAN(C30,C38,C46) -> 1.259921 | D3: =GEOMEAN(D30,D38,D46) -> 0.43679009 | E3: =GEOMEAN(E30,E38,E46) -> 3.9148676
A4: GSM/GPRS | B4: =1/C3 -> 0.79370053 | C4: 1 | D4: =GEOMEAN(D31,D39,D47) -> 0.38157116 | E4: =GEOMEAN(E31,E39,E47) -> 3.5568933
A5: Sigfox | B5: =1/D3 -> 2.2894292 | C5: =1/D4 -> 2.6207431 | D5: 1 | E5: =GEOMEAN(E32,E40,E48) -> 7.2304268
A6: Zigbee | B6: =1/E3 -> 0.25543648 | C6: =1/E4 -> 0.28114422 | D6: =1/E5 -> 0.13830442 | E6: 1
A7: Suma | B7: =SUM(B3:B6) -> 4.3385663 | C7: =SUM(C3:C6) -> 5.1618084 | D7: =SUM(D3:D6) -> 1.9566657 | E7: =SUM(E3:E6) -> 15.702188
A9: Normalizada | F9: Vector prioridad
B10: =B3/B$7 -> 0.23049089 | C10: =C3/C$7 -> 0.2440852 | D10: =D3/D$7 -> 0.22323184 | E10: =E3/E$7 -> 0.24931989 | F10: =AVERAGE(B10:E10) -> 0.23678196
B11: =B4/B$7 -> 0.18294074 | C11: =C4/C$7 -> 0.19373055 | D11: =D4/D$7 -> 0.19501091 | E11: =E4/E$7 -> 0.22652215 | F11: =AVERAGE(B11:E11) -> 0.19955109
B12: =B5/B$7 -> 0.52769259 | C12: =C5/C$7 -> 0.50771802 | D12: =D5/D$7 -> 0.51107351 | E12: =E5/E$7 -> 0.46047257 | F12: =AVERAGE(B12:E12) -> 0.50173917
B13: =B6/B$7 -> 0.058875781 | C13: =C6/C$7 -> 0.054466226 | D13: =D6/D$7 -> 0.070683727 | E13: =E6/E$7 -> 0.063685393 | F13: =AVERAGE(B13:E13) -> 0.061927782
A15: Verificación de consistencia
A16: A·w (LoRaWAN) | B16: =B3*$F$10 + C3*$F$11 + D3*$F$12 + E3*$F$13 -> 0.94979434 | C16: =B16/F10 -> 4.0112615 | D16: lambda parcial
A17: A·w (GSM/GPRS) | B17: =B4*$F$10 + C4*$F$11 + D4*$F$12 + E4*$F$13 -> 0.79920476 | C17: =B17/F11 -> 4.0050133 | D17: lambda parcial
A18: A·w (Sigfox) | B18: =B5*$F$10 + C5*$F$11 + D5*$F$12 + E5*$F$13 -> 2.0145711 | C18: =B18/F12 -> 4.0151761 | D18: lambda parcial
A19: A·w (Zigbee) | B19: =B6*$F$10 + C6*$F$11 + D6*$F$12 + E6*$F$13 -> 0.24790591 | C19: =B19/F13 -> 4.0031454 | D19: lambda parcial
A20: lambda_max | B20: =AVERAGE(C16:C19) -> 4.0086491
A21: CI = (lambda_max - n) / (n - 1) | B21: =(B20-4)/(4-1) -> 0.0028830214
A22: RI (tabla Saaty, n=4) | B22: 0.9
A23: CR = CI / RI | B23: =B21/B22 -> 0.0032033572
A24: ¿Consistente? (CR < 0.10) | B24: =IF(B23<0.1,"Sí, consistente","No, revisar juicios") -> Sí, consistente
A26: Juicios individuales de los 3 expertos (entrada de GEOMEAN() de arriba)
A28: Experto 1: Ingeniero electrónico (experto en hardware y telecomunicaciones)
B29: LoRaWAN | C29: GSM/GPRS | D29: Sigfox | E29: Zigbee
A30: LoRaWAN | B30: 1 | C30: 1 | D30: 0.333333 | E30: 5
A31: GSM/GPRS | B31: =1/C30 -> 1 | C31: 1 | D31: 0.333333 | E31: 5
A32: Sigfox | B32: =1/D30 -> 3.000003 | C32: =1/D31 -> 3.000003 | D32: 1 | E32: 9
A33: Zigbee | B33: =1/E30 -> 0.2 | C33: =1/E31 -> 0.2 | D33: =1/E32 -> 0.11111111 | E33: 1
A36: Experto 2: Ingeniero agrónomo (experto en agricultura)
B37: LoRaWAN | C37: GSM/GPRS | D37: Sigfox | E37: Zigbee
A38: LoRaWAN | B38: 1 | C38: 1 | D38: 0.5 | E38: 3
A39: GSM/GPRS | B39: =1/C38 -> 1 | C39: 1 | D39: 0.5 | E39: 3
A40: Sigfox | B40: =1/D38 -> 2 | C40: =1/D39 -> 2 | D40: 1 | E40: 6
A41: Zigbee | B41: =1/E38 -> 0.33333333 | C41: =1/E39 -> 0.33333333 | D41: =1/E40 -> 0.16666667 | E41: 1
A44: Experto 3: Técnico de campo (experto en la problemática, Sierra Nevada)
B45: LoRaWAN | C45: GSM/GPRS | D45: Sigfox | E45: Zigbee
A46: LoRaWAN | B46: 1 | C46: 2 | D46: 0.5 | E46: 4
A47: GSM/GPRS | B47: =1/C46 -> 0.5 | C47: 1 | D47: 0.333333 | E47: 3
A48: Sigfox | B48: =1/D46 -> 2 | C48: =1/D47 -> 3.000003 | D48: 1 | E48: 7
...

Sheet Autonomía
A1: AHP, Autonomía | B1: Media geométrica de 3 expertos (ver juicios individuales más abajo, filas 26+). LoRaWAN ~10 años >> Sigfox 1.5-2.5a ≈ Zigbee 1-2a >> GSM/GPRS (picos de hasta 2A en ráfaga GPRS)
B2: LoRaWAN | C2: GSM/GPRS | D2: Sigfox | E2: Zigbee
A3: LoRaWAN | B3: 1 | C3: =GEOMEAN(C30,C38,C46) -> 6.8040921 | D3: =GEOMEAN(D30,D38,D46) -> 2.8844991 | E3: =GEOMEAN(E30,E38,E46) -> 3.9148676
A4: GSM/GPRS | B4: =1/C3 -> 0.14697038 | C4: 1 | D4: =GEOMEAN(D31,D39,D47) -> 0.34668052 | E4: =GEOMEAN(E31,E39,E47) -> 0.34668052
A5: Sigfox | B5: =1/D3 -> 0.34668064 | C5: =1/D4 -> 2.8845001 | D5: 1 | E5: =GEOMEAN(E32,E40,E48) -> 1
A6: Zigbee | B6: =1/E3 -> 0.25543648 | C6: =1/E4 -> 2.8845001 | D6: =1/E5 -> 1 | E6: 1
A7: Suma | B7: =SUM(B3:B6) -> 1.7490875 | C7: =SUM(C3:C6) -> 13.573092 | D7: =SUM(D3:D6) -> 5.2311797 | E7: =SUM(E3:E6) -> 6.2615482
A9: Normalizada | F9: Vector prioridad
B10: =B3/B$7 -> 0.57172669 | C10: =C3/C$7 -> 0.5012927 | D10: =D3/D$7 -> 0.5514051 | E10: =E3/E$7 -> 0.62522359 | F10: =AVERAGE(B10:E10) -> 0.56241202
B11: =B4/B$7 -> 0.084026888 | C11: =C4/C$7 -> 0.073675179 | D11: =D4/D$7 -> 0.066271959 | E11: =E4/E$7 -> 0.055366582 | F11: =AVERAGE(B11:E11) -> 0.069835152
B12: =B5/B$7 -> 0.19820657 | C12: =C5/C$7 -> 0.21251606 | D12: =D5/D$7 -> 0.19116147 | E12: =E5/E$7 -> 0.15970491 | F12: =AVERAGE(B12:E12) -> 0.19039725
B13: =B6/B$7 -> 0.14603985 | C13: =C6/C$7 -> 0.21251606 | D13: =D6/D$7 -> 0.19116147 | E13: =E6/E$7 -> 0.15970491 | F13: =AVERAGE(B13:E13) -> 0.17735557
A15: Verificación de consistencia
A16: A·w (LoRaWAN) | B16: =B3*$F$10 + C3*$F$11 + D3*$F$12 + E3*$F$13 -> 2.2811011 | C16: =B16/F10 -> 4.0559253 | D16: lambda parcial
A17: A·w (GSM/GPRS) | B17: =B4*$F$10 + C4*$F$11 + D4*$F$12 + E4*$F$13 -> 0.2799858 | C17: =B17/F11 -> 4.0092388 | D17: lambda parcial
A18: A·w (Sigfox) | B18: =B5*$F$10 + C5*$F$11 + D5*$F$12 + E5*$F$13 -> 0.76416969 | C18: =B18/F12 -> 4.0135541 | D18: lambda parcial
A19: A·w (Zigbee) | B19: =B6*$F$10 + C6*$F$11 + D6*$F$12 + E6*$F$13 -> 0.71285288 | C19: =B19/F13 -> 4.019343 | D19: lambda parcial
A20: lambda_max | B20: =AVERAGE(C16:C19) -> 4.0245153
A21: CI = (lambda_max - n) / (n - 1) | B21: =(B20-4)/(4-1) -> 0.008171768
A22: RI (tabla Saaty, n=4) | B22: 0.9
A23: CR = CI / RI | B23: =B21/B22 -> 0.0090797422
A24: ¿Consistente? (CR < 0.10) | B24: =IF(B23<0.1,"Sí, consistente","No, revisar juicios") -> Sí, consistente
A26: Juicios individuales de los 3 expertos (entrada de GEOMEAN() de arriba)
A28: Experto 1: Ingeniero electrónico (experto en hardware y telecomunicaciones)
B29: LoRaWAN | C29: GSM/GPRS | D29: Sigfox | E29: Zigbee
A30: LoRaWAN | B30: 1 | C30: 5 | D30: 2 | E30: 3
A31: GSM/GPRS | B31: =1/C30 -> 0.2 | C31: 1 | D31: 0.5 | E31: 0.5
A32: Sigfox | B32: =1/D30 -> 0.5 | C32: =1/D31 -> 2 | D32: 1 | E32: 1
A33: Zigbee | B33: =1/E30 -> 0.33333333 | C33: =1/E31 -> 2 | D33: =1/E32 -> 1 | E33: 1
A36: Experto 2: Ingeniero agrónomo (experto en agricultura)
B37: LoRaWAN | C37: GSM/GPRS | D37: Sigfox | E37: Zigbee
A38: LoRaWAN | B38: 1 | C38: 7 | D38: 3 | E38: 4
A39: GSM/GPRS | B39: =1/C38 -> 0.14285714 | C39: 1 | D39: 0.333333 | E39: 0.333333
A40: Sigfox | B40: =1/D38 -> 0.33333333 | C40: =1/D39 -> 3.000003 | D40: 1 | E40: 1
A41: Zigbee | B41: =1/E38 -> 0.25 | C41: =1/E39 -> 3.000003 | D41: =1/E40 -> 1 | E41: 1
A44: Experto 3: Técnico de campo (experto en la problemática, Sierra Nevada)
B45: LoRaWAN | C45: GSM/GPRS | D45: Sigfox | E45: Zigbee
A46: LoRaWAN | B46: 1 | C46: 9 | D46: 4 | E46: 5
A47: GSM/GPRS | B47: =1/C46 -> 0.11111111 | C47: 1 | D47: 0.25 | E47: 0.25
A48: Sigfox | B48: =1/D46 -> 0.25 | C48: =1/D47 -> 4 | D48: 1 | E48: 1
...

Sheet Infraestructura
A1: AHP, Infraestructura | B1: Media geométrica de 3 expertos (ver juicios individuales más abajo, filas 26+). Sigfox: red nacional desplegada (WND/Phaxsi) >> GSM/GPRS: cobertura celular real en retirada > LoRaWAN≈Zigbee: sin red de operador
B2: LoRaWAN | C2: GSM/GPRS | D2: Sigfox | E2: Zigbee
A3: LoRaWAN | B3: 1 | C3: =GEOMEAN(C30,C38,C46) -> 0.34668052 | D3: =GEOMEAN(D30,D38,D46) -> 0.16465838 | E3: =GEOMEAN(E30,E38,E46) -> 1
A4: GSM/GPRS | B4: =1/C3 -> 2.8845001 | C4: 1 | D4: =GEOMEAN(D31,D39,D47) -> 0.5 | E4: =GEOMEAN(E31,E39,E47) -> 2.8844991
A5: Sigfox | B5: =1/D3 -> 6.07318 | C5: =1/D4 -> 2 | D5: 1 | E5: =GEOMEAN(E32,E40,E48) -> 5.7689983
A6: Zigbee | B6: =1/E3 -> 1 | C6: =1/E4 -> 0.34668064 | D6: =1/E5 -> 0.17334032 | E6: 1
A7: Suma | B7: =SUM(B3:B6) -> 10.95768 | C7: =SUM(C3:C6) -> 3.6933612 | D7: =SUM(D3:D6) -> 1.8379987 | E7: =SUM(E3:E6) -> 10.653497
A9: Normalizada | F9: Vector prioridad
B10: =B3/B$7 -> 0.091260193 | C10: =C3/C$7 -> 0.09386586 | D10: =D3/D$7 -> 0.089585691 | E10: =E3/E$7 -> 0.093865888 | F10: =AVERAGE(B10:E10) -> 0.092144408
B11: =B4/B$7 -> 0.26324004 | C11: =C4/C$7 -> 0.27075608 | D11: =D4/D$7 -> 0.27203501 | E11: =E4/E$7 -> 0.27075607 | F11: =AVERAGE(B11:E11) -> 0.2691968
B12: =B5/B$7 -> 0.55423958 | C12: =C5/C$7 -> 0.54151217 | D12: =D5/D$7 -> 0.54407002 | E12: =E5/E$7 -> 0.54151215 | F12: =AVERAGE(B12:E12) -> 0.54533348
B13: =B6/B$7 -> 0.091260193 | C13: =C6/C$7 -> 0.093865891 | D13: =D6/D$7 -> 0.094309271 | E13: =E6/E$7 -> 0.093865888 | F13: =AVERAGE(B13:E13) -> 0.093325311
A15: Verificación de consistencia
A16: A·w (LoRaWAN) | B16: =B3*$F$10 + C3*$F$11 + D3*$F$12 + E3*$F$13 -> 0.36858874 | C16: =B16/F10 -> 4.0001205 | D16: lambda parcial
A17: A·w (GSM/GPRS) | B17: =B4*$F$10 + C4*$F$11 + D4*$F$12 + E4*$F$13 -> 1.0768509 | C17: =B17/F11 -> 4.0002365 | D17: lambda parcial
A18: A·w (Sigfox) | B18: =B5*$F$10 + C5*$F$11 + D5*$F$12 + E5*$F$13 -> 2.1817302 | C18: =B18/F12 -> 4.0007267 | D18: lambda parcial
A19: A·w (Zigbee) | B19: =B6*$F$10 + C6*$F$11 + D6*$F$12 + E6*$F$13 -> 0.37332332 | C19: =B19/F13 -> 4.0002365 | D19: lambda parcial
A20: lambda_max | B20: =AVERAGE(C16:C19) -> 4.0003301
A21: CI = (lambda_max - n) / (n - 1) | B21: =(B20-4)/(4-1) -> 0.00011002001
A22: RI (tabla Saaty, n=4) | B22: 0.9
A23: CR = CI / RI | B23: =B21/B22 -> 0.00012224445
A24: ¿Consistente? (CR < 0.10) | B24: =IF(B23<0.1,"Sí, consistente","No, revisar juicios") -> Sí, consistente
A26: Juicios individuales de los 3 expertos (entrada de GEOMEAN() de arriba)
A28: Experto 1: Ingeniero electrónico (experto en hardware y telecomunicaciones)
B29: LoRaWAN | C29: GSM/GPRS | D29: Sigfox | E29: Zigbee
A30: LoRaWAN | B30: 1 | C30: 0.25 | D30: 0.125 | E30: 1
A31: GSM/GPRS | B31: =1/C30 -> 4 | C31: 1 | D31: 0.5 | E31: 4
A32: Sigfox | B32: =1/D30 -> 8 | C32: =1/D31 -> 2 | D32: 1 | E32: 8
A33: Zigbee | B33: =1/E30 -> 1 | C33: =1/E31 -> 0.25 | D33: =1/E32 -> 0.125 | E33: 1
A36: Experto 2: Ingeniero agrónomo (experto en agricultura)
B37: LoRaWAN | C37: GSM/GPRS | D37: Sigfox | E37: Zigbee
A38: LoRaWAN | B38: 1 | C38: 0.5 | D38: 0.25 | E38: 1
A39: GSM/GPRS | B39: =1/C38 -> 2 | C39: 1 | D39: 0.5 | E39: 2
A40: Sigfox | B40: =1/D38 -> 4 | C40: =1/D39 -> 2 | D40: 1 | E40: 4
A41: Zigbee | B41: =1/E38 -> 1 | C41: =1/E39 -> 0.5 | D41: =1/E40 -> 0.25 | E41: 1
A44: Experto 3: Técnico de campo (experto en la problemática, Sierra Nevada)
B45: LoRaWAN | C45: GSM/GPRS | D45: Sigfox | E45: Zigbee
A46: LoRaWAN | B46: 1 | C46: 0.333333 | D46: 0.142857 | E46: 1
A47: GSM/GPRS | B47: =1/C46 -> 3.000003 | C47: 1 | D47: 0.5 | E47: 3
A48: Sigfox | B48: =1/D46 -> 7.000007 | C48: =1/D47 -> 2 | D48: 1 | E48: 6
...

Sheet Madurez
A1: AHP, Madurez | B1: Media geométrica de 3 expertos (ver juicios individuales más abajo, filas 26+). LoRaWAN≈Zigbee: estándares estables en crecimiento >> GSM/GPRS: maduro pero con apagado activo de 2G >> Sigfox: insolvencia real 2022
B2: LoRaWAN | C2: GSM/GPRS | D2: Sigfox | E2: Zigbee
A3: LoRaWAN | B3: 1 | C3: =GEOMEAN(C30,C38,C46) -> 2.2894285 | D3: =GEOMEAN(D30,D38,D46) -> 6 | E3: =GEOMEAN(E30,E38,E46) -> 1
A4: GSM/GPRS | B4: =1/C3 -> 0.43679023 | C4: 1 | D4: =GEOMEAN(D31,D39,D47) -> 1.8171206 | E4: =GEOMEAN(E31,E39,E47) -> 0.43679009
A5: Sigfox | B5: =1/D3 -> 0.16666667 | C5: =1/D4 -> 0.55032121 | D5: 1 | E5: =GEOMEAN(E32,E40,E48) -> 0.16666672
A6: Zigbee | B6: =1/E3 -> 1 | C6: =1/E4 -> 2.2894292 | D6: =1/E5 -> 5.999998 | E6: 1
A7: Suma | B7: =SUM(B3:B6) -> 2.6034569 | C7: =SUM(C3:C6) -> 6.1291789 | D7: =SUM(D3:D6) -> 14.817119 | E7: =SUM(E3:E6) -> 2.6034568
A9: Normalizada | F9: Vector prioridad
B10: =B3/B$7 -> 0.38410469 | C10: =C3/C$7 -> 0.37352939 | D10: =D3/D$7 -> 0.40493703 | E10: =E3/E$7 -> 0.3841047 | F10: =AVERAGE(B10:E10) -> 0.38666895
B11: =B4/B$7 -> 0.16777318 | C11: =C4/C$7 -> 0.16315399 | D11: =D4/D$7 -> 0.12263657 | E11: =E4/E$7 -> 0.16777313 | F11: =AVERAGE(B11:E11) -> 0.15533422
B12: =B5/B$7 -> 0.064017448 | C12: =C5/C$7 -> 0.089787101 | D12: =D5/D$7 -> 0.067489505 | E12: =E5/E$7 -> 0.064017472 | F12: =AVERAGE(B12:E12) -> 0.071327881
B13: =B6/B$7 -> 0.38410469 | C13: =C6/C$7 -> 0.37352952 | D13: =D6/D$7 -> 0.4049369 | E13: =E6/E$7 -> 0.3841047 | F13: =AVERAGE(B13:E13) -> 0.38666895
A15: Verificación de consistencia
A16: A·w (LoRaWAN) | B16: =B3*$F$10 + C3*$F$11 + D3*$F$12 + E3*$F$13 -> 1.5569318 | C16: =B16/F10 -> 4.0265239 | D16: lambda parcial
A17: A·w (GSM/GPRS) | B17: =B4*$F$10 + C4*$F$11 + D4*$F$12 + E4*$F$13 -> 0.62273196 | C17: =B17/F11 -> 4.0089813 | D17: lambda parcial
A18: A·w (Sigfox) | B18: =B5*$F$10 + C5*$F$11 + D5*$F$12 + E5*$F$13 -> 0.28570127 | C18: =B18/F12 -> 4.0054641 | D18: lambda parcial
A19: A·w (Zigbee) | B19: =B6*$F$10 + C6*$F$11 + D6*$F$12 + E6*$F$13 -> 1.5569317 | C19: =B19/F13 -> 4.0265238 | D19: lambda parcial
A20: lambda_max | B20: =AVERAGE(C16:C19) -> 4.0168733
A21: CI = (lambda_max - n) / (n - 1) | B21: =(B20-4)/(4-1) -> 0.0056244229
A22: RI (tabla Saaty, n=4) | B22: 0.9
A23: CR = CI / RI | B23: =B21/B22 -> 0.0062493588
A24: ¿Consistente? (CR < 0.10) | B24: =IF(B23<0.1,"Sí, consistente","No, revisar juicios") -> Sí, consistente
A26: Juicios individuales de los 3 expertos (entrada de GEOMEAN() de arriba)
A28: Experto 1: Ingeniero electrónico (experto en hardware y telecomunicaciones)
B29: LoRaWAN | C29: GSM/GPRS | D29: Sigfox | E29: Zigbee
A30: LoRaWAN | B30: 1 | C30: 3 | D30: 9 | E30: 1
A31: GSM/GPRS | B31: =1/C30 -> 0.33333333 | C31: 1 | D31: 3 | E31: 0.333333
A32: Sigfox | B32: =1/D30 -> 0.11111111 | C32: =1/D31 -> 0.33333333 | D32: 1 | E32: 0.111111
A33: Zigbee | B33: =1/E30 -> 1 | C33: =1/E31 -> 3.000003 | D33: =1/E32 -> 9.000009 | E33: 1
A36: Experto 2: Ingeniero agrónomo (experto en agricultura)
B37: LoRaWAN | C37: GSM/GPRS | D37: Sigfox | E37: Zigbee
A38: LoRaWAN | B38: 1 | C38: 2 | D38: 6 | E38: 1
A39: GSM/GPRS | B39: =1/C38 -> 0.5 | C39: 1 | D39: 2 | E39: 0.5
A40: Sigfox | B40: =1/D38 -> 0.16666667 | C40: =1/D39 -> 0.5 | D40: 1 | E40: 0.166667
A41: Zigbee | B41: =1/E38 -> 1 | C41: =1/E39 -> 2 | D41: =1/E40 -> 5.999988 | E41: 1
A44: Experto 3: Técnico de campo (experto en la problemática, Sierra Nevada)
B45: LoRaWAN | C45: GSM/GPRS | D45: Sigfox | E45: Zigbee
A46: LoRaWAN | B46: 1 | C46: 2 | D46: 4 | E46: 1
A47: GSM/GPRS | B47: =1/C46 -> 0.5 | C47: 1 | D47: 1 | E47: 0.5
A48: Sigfox | B48: =1/D46 -> 0.25 | C48: =1/D47 -> 1 | D48: 1 | E48: 0.25
...

Sheet Síntesis
A1: Tecnología
B2: Alcance | C2: Autonomía | D2: Infraestructura | E2: Madurez | F2: Prioridad global | G2: Ranking
A3: Peso del criterio | B3: =Criterios!F11 -> #NUM! | C3: =Criterios!F12 -> #NUM! | D3: =Criterios!F13 -> #NUM! | E3: =Criterios!F14 -> #NUM!
A4: LoRaWAN | B4: =Alcance!F10 -> 0.23678196 | C4: =Autonomía!F10 -> 0.56241202 | D4: =Infraestructura!F10 -> 0.092144408 | E4: =Madurez!F10 -> 0.38666895 | F4: =SUMPRODUCT(B4:E4,B$3:E$3) -> #NUM! | G4: =RANK(F4,F$4:F$7) -> #NUM!
A5: GSM/GPRS | B5: =Alcance!F11 -> 0.19955109 | C5: =Autonomía!F11 -> 0.069835152 | D5: =Infraestructura!F11 -> 0.2691968 | E5: =Madurez!F11 -> 0.15533422 | F5: =SUMPRODUCT(B5:E5,B$3:E$3) -> #NUM! | G5: =RANK(F5,F$4:F$7) -> #NUM!
A6: Sigfox | B6: =Alcance!F12 -> 0.50173917 | C6: =Autonomía!F12 -> 0.19039725 | D6: =Infraestructura!F12 -> 0.54533348 | E6: =Madurez!F12 -> 0.071327881 | F6: =SUMPRODUCT(B6:E6,B$3:E$3) -> #NUM! | G6: =RANK(F6,F$4:F$7) -> #NUM!
A7: Zigbee | B7: =Alcance!F13 -> 0.061927782 | C7: =Autonomía!F13 -> 0.17735557 | D7: =Infraestructura!F13 -> 0.093325311 | E7: =Madurez!F13 -> 0.38666895 | F7: =SUMPRODUCT(B7:E7,B$3:E$3) -> #NUM! | G7: =RANK(F7,F$4:F$7) -> #NUM!
A9: Ganador | B9: =INDEX(A4:A7,MATCH(MAX(F4:F7),F4:F7,0)) -> #NUM! | C9: con prioridad global de | D9: =MAX(F4:F7) -> #NUM!
